<?xml version="1.0"?>
<robot name="NEma" xmlns:xacro="http://www.ros.org/wiki/xacro">

    <link name="world"></link>

    <link name="base_link">
        <visual>
            <origin xyz="0.0 0.0 0.050" rpy="0.0 0.0 0.0"/> 
            <geometry>
                <box size="0.350 0.350 0.100"/>
            </geometry>
        </visual>
        <collision>
            <origin xyz="0.0 0.0 0.050" rpy="0.0 0.0 0.0"/>
            <geometry>
                <box size="0.350 0.350 0.100"/>
            </geometry>
        </collision>
        <inertial>
            <origin xyz="0 0 0.050" rpy="0.0 0.0 0.0"/>
            <mass value="0.1"/>
            <inertia ixx="0.1" ixy="0.0" ixz="0.0" iyy="0.1" iyz="0.0" izz="0.1"/>
        </inertial>
    </link>

    <link name="body_link">
        <visual>
            <origin xyz="0.0 0.0 0.200" rpy="0.0 0.0 0.0"/> 
            <geometry>
                <box size="0.350 0.350 0.400"/>
            </geometry>
        </visual>
        <collision>
            <origin xyz="0.0 0.0 0.200" rpy="0.0 0.0 0.0"/>
            <geometry>
                <box size="0.350 0.350 0.400"/>
            </geometry>
        </collision>
        <inertial>
            <origin xyz="0 0 0.200" rpy="0.0 0.0 0.0"/>
            <mass value="0.4"/>
            <inertia ixx="0.4" ixy="0.0" ixz="0.0" iyy="0.4" iyz="0.0" izz="0.4"/>
        </inertial>
    </link>

    <link name="face_link">
        <visual>
            <origin xyz="0.0 0.0 0.075" rpy="0.0 0.0 0.0"/> 
            <geometry>
                <box size="0.200 0.200 0.150"/>
            </geometry>
        </visual>
        <collision>
            <origin xyz="0.0 0.0 0.075" rpy="0.0 0.0 0.0"/>
            <geometry>
                <box size="0.200 0.200 0.150"/>
            </geometry>
        </collision>
        <inertial>
            <origin xyz="0 0 0.075" rpy="0.0 0.0 0.0"/>
            <mass value="0.08"/>
            <inertia ixx="0.08" ixy="0.0" ixz="0.0" iyy="0.08" iyz="0.0" izz="0.08"/>
        </inertial>
    </link>

    <link name="face_intermediate_link">
        <inertial>
            <origin xyz="0 0 0" rpy="0 0 0"/>
            <mass value="0.0001"/>
            <inertia ixx="0.0001" ixy="0.0" ixz="0.0" iyy="0.0001" iyz="0.0" izz="0.0001"/>
        </inertial>
    </link>
    <link name="right_arm1">
        <visual>
            <origin xyz="0.0 0.0 -0.075" rpy="0.0 0.0 0.0"/>
            <geometry>
                <box size="0.050 0.050 0.150"/>
            </geometry>
        </visual>
        <collision>
            <origin xyz="0.0 0.0 -0.075" rpy="0.0 0.0 0.0"/>
            <geometry>
                <box size="0.050 0.050 0.150"/>
            </geometry>
        </collision>
        <inertial>
            <origin xyz="0.0 0.0 -0.075" rpy="0.0 0.0 0.0"/>
            <mass value="0.06"/>
            <inertia ixx="0.06" ixy="0.0" ixz="0.0" iyy="0.06" iyz="0.0" izz="0.06"/>
        </inertial>
    </link>

    <link name="right_arm2">
        <visual>
            <origin xyz="0.0 0.0 -0.0375" rpy="0.0 0.0 0.0"/>
            <geometry>
                <box size="0.050 0.050 0.075"/>
            </geometry>
        </visual>
        <collision>
            <origin xyz="0.0 0.0 -0.0375" rpy="0.0 0.0 0.0"/>
            <geometry>
                <box size="0.050 0.050 0.075"/>
            </geometry>
        </collision>
        <inertial>
            <origin xyz="0.0 0.0 -0.0375" rpy="0.0 0.0 0.0"/>
            <mass value="0.03"/>
            <inertia ixx="0.03" ixy="0.0" ixz="0.0" iyy="0.03" iyz="0.0" izz="0.03"/>
        </inertial>
    </link>
    <link name="right_arm3">
        <visual>
            <origin xyz="0.0 0.00 -0.03" rpy="0.0 0.0 0.0"/>
            <geometry>
                <box size="0.050 0.050 0.060"/>
            </geometry>
        </visual>    
        <collision>
            <origin xyz="0.0 0.0 -0.03" rpy="0.0 0.0 0.0"/>
            <geometry>
                <box size="0.050 0.050 0.060"/>
            </geometry>
        </collision>  
        <inertial>
            <origin xyz="0.0 0.0 -0.030" rpy="0.0 0.0 0.0"/>
            <mass value="0.01"/>
            <inertia ixx="0.01" ixy="0.0" ixz="0.0" iyy="0.01" iyz="0.0" izz="0.01"/>
        </inertial>  
    </link>

    <link name="left_arm1">
        <visual>
            <origin xyz="0.0 0.0 -0.075" rpy="0.0 0.0 0.0"/>
            <geometry>
                <box size="0.050 0.050 0.150"/>
            </geometry>
        </visual>
        <collision>
            <origin xyz="0.0 0.0 -0.075" rpy="0.0 0.0 0.0"/>
            <geometry>
                <box size="0.050 0.050 0.150"/>
            </geometry>
        </collision>
        <inertial>
            <origin xyz="0.0 0.0 -0.075" rpy="0.0 0.0 0.0"/>
            <mass value="0.06"/>
            <inertia ixx="0.06" ixy="0.0" ixz="0.0" iyy="0.06" iyz="0.0" izz="0.06"/>
        </inertial>
    </link>

    <link name="left_arm2">
        <visual>
            <origin xyz="0.0 0.0 -0.0375" rpy="0.0 0.0 0.0"/>
            <geometry>
                <box size="0.050 0.050 0.075"/>
            </geometry>
        </visual>
        <collision>
            <origin xyz="0.0 0.0 -0.0375" rpy="0.0 0.0 0.0"/>
            <geometry>
                <box size="0.050 0.050 0.075"/>
            </geometry>
        </collision>
        <inertial>
            <origin xyz="0.0 0.0 -0.0375" rpy="0.0 0.0 0.0"/>
            <mass value="0.03"/>
            <inertia ixx="0.03" ixy="0.0" ixz="0.0" iyy="0.03" iyz="0.0" izz="0.03"/>
        </inertial>
    </link>
    <link name="left_arm3">
        <visual>
            <origin xyz="0.0 0.00 -0.03" rpy="0.0 0.0 0.0"/>
            <geometry>
                <box size="0.050 0.050 0.060"/>
            </geometry>
        </visual>    
        <collision>
            <origin xyz="0.0 0.0 -0.03" rpy="0.0 0.0 0.0"/>
            <geometry>
                <box size="0.050 0.050 0.060"/>
            </geometry>
        </collision>  
        <inertial>
            <origin xyz="0.0 0.0 -0.030" rpy="0.0 0.0 0.0"/>
            <mass value="0.01"/>
            <inertia ixx="0.01" ixy="0.0" ixz="0.0" iyy="0.01" iyz="0.0" izz="0.01"/>
        </inertial>  
    </link>
    <joint name="fixed" type="fixed">
        <origin xyz="0.0 0.0 0.0" rpy="0.0 0.0 0.0"/>
        <parent link="world"/>
        <child link="base_link"/>
    </joint>

    <joint name="body_joint" type="revolute">
        <safety_controller k_position="100.0" k_velocity="40.0" soft_lower_limit="-0.8" soft_upper_limit="0.8"/>
        <origin rpy="0 0 0" xyz="0 0 0.100"/>
        <parent link="base_link"/>
        <child link="body_link"/>
        <axis xyz="0 0 1"/>
        <limit effort="30.0" lower="-0.85" upper="0.85" velocity="10.0"/>
    </joint>

    <joint name="face_joint_z" type="revolute">
        <safety_controller k_position="100.0" k_velocity="40.0" soft_lower_limit="-0.8" soft_upper_limit="0.8"/>
        <origin rpy="0 0 0" xyz="0 0 0.400"/>
        <parent link="body_link"/>
        <child link="face_intermediate_link"/>
        <axis xyz="0 0 1"/> 
        <limit effort="30.0" lower="-0.85" upper="0.85" velocity="10.0"/>
    </joint>

    <joint name="face_joint_x" type="revolute">
        <safety_controller k_position="100.0" k_velocity="40.0" soft_lower_limit="-0.8" soft_upper_limit="0.8"/>
        <origin rpy="0 0 0" xyz="0 0 0.0"/> 
        <parent link="face_intermediate_link"/>
        <child link="face_link"/>
        <axis xyz="1 0 0"/> 
        <limit effort="30.0" lower="-0.85" upper="0.85" velocity="10.0"/>
    </joint>

    <joint name="right_joint1" type="revolute">
        <safety_controller k_position="100.0" k_velocity="40.0" soft_lower_limit="0" soft_upper_limit="0.8"/>
        <origin rpy="0.02 0 0" xyz="0.200 0 0.300"/>
        <parent link="body_link"/>
        <child link="right_arm1"/>
        <axis xyz="1 0 0"/>
        <limit effort="30.0" lower="-0.05" upper="0.85" velocity="10.0"/>
    </joint>
    <joint name="right_joint2" type="revolute">
        <safety_controller k_position="100.0" k_velocity="40.0" soft_lower_limit="0" soft_upper_limit="0.4"/>
        <origin rpy="0.02 0 0" xyz="0.050 0 -0.125"/>
        <parent link="right_arm1"/>
        <child link="right_arm2"/>
        <axis xyz="1 0 0"/>
        <limit effort="30.0" lower="-0.05" upper="0.45" velocity="10.0"/>
    </joint>
    <joint name="right_joint3" type="revolute">
        <safety_controller k_position="100.0" k_velocity="40.0" soft_lower_limit="0" soft_upper_limit="0.2"/>
        <origin rpy="0.02 0 0" xyz="0.050 0 -0.055"/>
        <parent link="right_arm2"/>
        <child link="right_arm3"/>
        <axis xyz="1 0 0"/>
        <limit effort="30.0" lower="-0.05" upper="0.25" velocity="10.0"/>
    </joint>

    <joint name="left_joint1" type="revolute">
        <safety_controller k_position="100.0" k_velocity="40.0" soft_lower_limit="0" soft_upper_limit="0.8"/>
        <origin rpy="0.02 0 0" xyz="-0.200 0 0.300"/>
        <parent link="body_link"/>
        <child link="left_arm1"/>
        <axis xyz="1 0 0"/>
        <limit effort="30.0" lower="-0.05" upper="0.85" velocity="10.0"/>
    </joint>
    <joint name="left_joint2" type="revolute">
        <safety_controller k_position="100.0" k_velocity="40.0" soft_lower_limit="0" soft_upper_limit="0.4"/>
        <origin rpy="0.02 0 0" xyz="-0.050 0 -0.125"/>
        <parent link="left_arm1"/>
        <child link="left_arm2"/>
        <axis xyz="1 0 0"/>
        <limit effort="30.0" lower="-0.05" upper="0.45" velocity="10.0"/>
    </joint>
    <joint name="left_joint3" type="revolute">
        <safety_controller k_position="100.0" k_velocity="40.0" soft_lower_limit="0" soft_upper_limit="0.2"/>
        <origin rpy="0.02 0 0" xyz="-0.050 0 -0.055"/>
        <parent link="left_arm2"/>
        <child link="left_arm3"/>
        <axis xyz="1 0 0"/>
        <limit effort="30.0" lower="-0.05" upper="0.25" velocity="10.0"/>
    </joint>
    <joint name="camera_mount_joint" type="fixed">
        <parent link="body_link"/>
        <child link="camera_link"/>
        <origin xyz="0.0 0.195 0.100" rpy="0 0 0"/>
    </joint>

    <link name="camera_link">
        <inertial>
            <mass value="0.1"/>
            <origin xyz="0 0 0"/>
            <inertia ixx="0.001" iyy="0.001" izz="0.001"
                    ixy="0" ixz="0" iyz="0"/>
        </inertial>

        <visual>
            <origin xyz="0 0 0" rpy="0 0 0"/>
            <geometry>
                <box size="0.04 0.04 0.04"/>
            </geometry>
            <material name="green">
                <color rgba= "0 1 0 1"/>
            </material>
        </visual>

        <collision>
            <geometry>
                <box size="0.04 0.04 0.04"/>
            </geometry>
        </collision>
    </link>

    <link name="camera_optical_link"/>

    <joint name="camera_optical_joint" type="fixed">
        <parent link="camera_link"/>
        <child link="camera_optical_link"/>
        <origin xyz="0 0 0" rpy="-1.5708 0 -1.5708"/>
    </joint>
</robot>